Workbook

Sheet Summary
C2: Test Report for Senao P2MP UBR630
C3: Image Version | G3: Release v1.0.0.124/125
C4: Tested By
C5: Image status
C6: Model No | G6: A60/A61 & UBR630/UBR650
C10: Index | G10: TOTAL | H10: PASS | I10: FAIL | J10: NOT TESTED | K10: NOT APPLICABLE | L10: NOT AVAILABLE | M10: Comments | N10: % Completion | O10: Automated Test cases
C11: RFC Results | G11: 13 | H11: 0 | I11: 0 | J11: 13 | K11: 0 | L11: 0 | M11: Single SU throughput is impacted | N11: =IF(G11-K11=0,0,(H11+I11+L11)/(G11-K11)) -> 0
C12: Sanity | G12: 115 | H12: =COUNTIF(Sanity!$K:$K,"PASS") -> 86 | I12: =COUNTIF(Sanity!$K:$K,"FAIL") -> 7 | J12: =COUNTIF(Sanity!$K:$K,"NOT TESTED") -> 0 | K12: =COUNTIF(Sanity!$K:$K,"NOT APPLICABLE") -> 1 | L12: =COUNTIF(Sanity!$K:$K,"NOT Available") -> 21 | N12: =IF(G12-K12=0,0,(H12+I12+L12)/(G12-K12)) -> 1
C13: Tx Power Measurement | G13: 1 | H13: 0 | I13: 0 | J13: 0 | K13: 0 | L13: 1 | N13: =IF(G13-K13=0,0,(H13+I13+L13)/(G13-K13)) -> 1
C14: GUI | G14: 139 | H14: =COUNTIF(GUI!$K:$K,"PASS") -> 131 | I14: =COUNTIF(GUI!$K:$K,"FAIL") -> 2 | J14: =COUNTIF(GUI!$K:$K,"NOT TESTED") -> 0 | K14: =COUNTIF(GUI!$K:$K,"NOT APPLICABLE") -> 0 | L14: =COUNTIF(GUI!$K:$K,"NOT Available") -> 6 | N14: =IF(G14-K14=0,0,(H14+I14+L14)/(G14-K14)) -> 1
C15: Throughput per MCS | G15: 192 | H15: 192 | I15: 0 | J15: 0 | K15: 0 | L15: 0 | N15: =IF(G15-K15=0,0,(H15+I15+L15)/(G15-K15)) -> 1
C16: ATPC | G16: 10 | H16: =COUNTIF(ATPC!$J:$J,"PASS") -> 0 | I16: =COUNTIF(ATPC!$J:$J,"FAIL") -> 0 | J16: =COUNTIF(ATPC!$J:$J,"NOT TESTED") -> 0 | K16: =COUNTIF(ATPC!$J:$J,"NOT APPLICABLE") -> 0 | L16: =COUNTIF(ATPC!$J:$J,"NOT Available") -> 10 | N16: =IF(G16-K16=0,0,(H16+I16+L16)/(G16-K16)) -> 1
C17: Jumbo Frames | G17: 10 | H17: =COUNTIF('Jumbo Frames'!$J:$J,"PASS") -> 10 | I17: =COUNTIF('Jumbo Frames'!$J:$J,"FAIL") -> 0 | J17: =COUNTIF('Jumbo Frames'!$J:$J,"NOT TESTED") -> 0 | K17: =COUNTIF('Jumbo Frames'!$J:$J,"NOT APPLICABLE") -> 0 | L17: =COUNTIF('Jumbo Frames'!$J:$J,"NOT Available") -> 0 | N17: =IF(G17-K17=0,0,(H17+I17+L17)/(G17-K17)) -> 1
C18: VLAN | G18: 59 | H18: =COUNTIF(VLAN!$J:$J,"PASS") -> 49 | I18: =COUNTIF(VLAN!$J:$J,"FAIL") -> 2 | J18: =COUNTIF(VLAN!$J:$J,"NOT TESTED") -> 0 | K18: =COUNTIF(VLAN!$J:$J,"NOT APPLICABLE") -> 2 | L18: =COUNTIF(VLAN!$J:$J,"NOT AVAILABLE") -> 6 | N18: =IF(G18-K18=0,0,(H18+I18+L18)/(G18-K18)) -> 1
C19: Functional | G19: 28 | H19: =COUNTIF(Functional!$J:$J,"PASS") -> 27 | I19: =COUNTIF(Functional!$J:$J,"FAIL") -> 0 | J19: =COUNTIF(Functional!$J:$J,"NOT TESTED") -> 0 | K19: =COUNTIF(Functional!$J:$J,"NOT APPLICABLE") -> 0 | L19: =COUNTIF(Functional!$J:$J,"NOT Available") -> 1 | M19: CPU Overload test case (1) | N19: =IF(G19-K19=0,0,(H19+I19+L19)/(G19-K19)) -> 1
C20: Link Test Tool | G20: 32 | H20: =COUNTIF('Link Test Tool'!$J:$J,"PASS") -> 25 | I20: =COUNTIF('Link Test Tool'!$J:$J,"FAIL") -> 1 | J20: =COUNTIF('Link Test Tool'!$J:$J,"NOT TESTED") -> 0 | K20: =COUNTIF('Link Test Tool'!$J:$J,"NOT APPLICABLE") -> 0 | L20: =COUNTIF('Link Test Tool'!$J:$J,"NOT AVAILABLE") -> 6 | N20: =IF(G20-K20=0,0,(H20+I20+L20)/(G20-K20)) -> 1
C21: Ethernet Test | G21: 23 | H21: =COUNTIF('Ethernet Test'!$F:$F,"PASS") -> 23 | I21: =COUNTIF('Ethernet Test'!$F:$F,"FAIL") -> 0 | J21: =COUNTIF('Ethernet Test'!$F:$F,"NOT TESTED") -> 0 | K21: =COUNTIF('Ethernet Test'!$F:$F,"NOT APPLICABLE") -> 0 | L21: =COUNTIF('Ethernet Test'!$F:$F,"NOT AVAILABLE") -> 0 | N21: =IF(G21-K21=0,0,(H21+I21+L21)/(G21-K21)) -> 1
C22: Arp & Bridge Table | G22: 11 | H22: =COUNTIF('Arp & Bridge Table'!$J:$J,"PASS") -> 11 | I22: =COUNTIF('Arp & Bridge Table'!$J:$J,"FAIL") -> 0 | J22: =COUNTIF('Arp & Bridge Table'!$J:$J,"NOT TESTED") -> 0 | K22: =COUNTIF('Arp & Bridge Table'!$J:$J,"NOT APPLICABLE") -> 0 | L22: =COUNTIF('Arp & Bridge Table'!$J:$J,"NOT AVAILABLE") -> 0 | N22: =IF(G22-K22=0,0,(H22+I22+L22)/(G22-K22)) -> 1
C23: Cable Length | G23: 20 | H23: 12 | I23: 8 | J23: 0 | K23: 0 | L23: 0 | N23: =IF(G23-K23=0,0,(H23+I23+L23)/(G23-K23)) -> 1
C24: QoS | G24: 40 | H24: =COUNTIF(QoS!$J:$J,"PASS") -> 40 | I24: =COUNTIF(QoS!$J:$J,"FAIL") -> 0 | J24: =COUNTIF(QoS!$J:$J,"NOT TESTED") -> 0 | K24: =COUNTIF(QoS!$J:$J,"NOT APPLICABLE") -> 0 | L24: =COUNTIF(QoS!$J:$J,"NOT AVAILABLE") -> 0 | N24: =IF(G24-K24=0,0,(H24+I24+L24)/(G24-K24)) -> 1
C25: DCS | G25: 18 | H25: =COUNTIF(DCS!$J:$J,"PASS") -> 10 | I25: =COUNTIF(DCS!$J:$J,"FAIL") -> 8 | J25: =COUNTIF(DCS!$J:$J,"NOT TESTED") -> 0 | K25: =COUNTIF(DCS!$J:$J,"NOT APPLICABLE") -> 0 | L25: =COUNTIF(DCS!$J:$J,"NOT AVAILABLE") -> 0 | N25: =IF(G25-K25=0,0,(H25+I25+L25)/(G25-K25)) -> 1
C26: DDRS | G26: 71 | H26: =COUNTIF(DDRS!$J:$J,"PASS") -> 61 | I26: =COUNTIF(DDRS!$J:$J,"FAIL") -> 6 | J26: =COUNTIF(DDRS!$J:$J,"NOT TESTED") -> 0 | K26: =COUNTIF(DDRS!$J:$J,"NOT APPLICABLE") -> 0 | L26: =COUNTIF(DDRS!$J:$J,"NOT AVAILABLE") -> 4 | N26: =IF(G26-K26=0,0,(H26+I26+L26)/(G26-K26)) -> 1
C27: OFDMA | G27: 20 | H27: =COUNTIF(OFDMA!$J:$J,"PASS") -> 0 | I27: =COUNTIF(OFDMA!$J:$J,"FAIL") -> 0 | J27: =COUNTIF(OFDMA!$J:$J,"NOT TESTED") -> 0 | K27: =COUNTIF(OFDMA!$J:$J,"NOT APPLICABLE") -> 0 | L27: =COUNTIF(OFDMA!$J:$J,"NOT AVAILABLE") -> 44 | N27: =IF(G27-K27=0,0,(H27+I27+L27)/(G27-K27)) -> 2.2
C28: MU-MIMO | G28: 19 | H28: =COUNTIF('MU-MIMO'!$J:$J,"PASS") -> 0 | I28: =COUNTIF('MU-MIMO'!$J:$J,"FAIL") -> 0 | J28: =COUNTIF('MU-MIMO'!$J:$J,"NOT TESTED") -> 0 | K28: =COUNTIF('MU-MIMO'!$J:$J,"NOT APPLICABLE") -> 0 | L28: =COUNTIF('MU-MIMO'!$J:$J,"NOT AVAILABLE") -> 19 | N28: =IF(G28-K28=0,0,(H28+I28+L28)/(G28-K28)) -> 1
C29: Spectrum Analyser & Site Survey | G29: 26 | H29: =COUNTIF('Spectrum Analyser & Site Survey'!$J:$J,"PASS") -> 23 | I29: =COUNTIF('Spectrum Analyser & Site Survey'!$J:$J,"FAIL") -> 2 | J29: =COUNTIF('Spectrum Analyser & Site Survey'!$J:$J,"NOT TESTED") -> 0 | K29: =COUNTIF('Spectrum Analyser & Site Survey'!$J:$J,"NOT APPLICABLE") -> 0 | L29: =COUNTIF('Spectrum Analyser & Site Survey'!$J:$J,"NOT AVAILABLE") -> 1 | N29: =IF(G29-K29=0,0,(H29+I29+L29)/(G29-K29)) -> 1
C30: IPv4 & IPv6 | G30: 49 | H30: =COUNTIF('IPv4 & IPv6'!$J:$J,"Pass") -> 49 | I30: =COUNTIF('IPv4 & IPv6'!$J:$J,"FAIL") -> 0 | J30: =COUNTIF('IPv4 & IPv6'!$J:$J,"NOT TESTED") -> 0 | K30: =COUNTIF('IPv4 & IPv6'!$J:$J,"NOT APPLICABLE") -> 0 | L30: =COUNTIF('IPv4 & IPv6'!$I:$I,"NOT AVAILABLE") -> 0 | N30: =IF(G30-K30=0,0,(H30+I30+L30)/(G30-K30)) -> 1
C31: DHCPv4 & DHCPv6 | G31: 58 | H31: =COUNTIF('DHCPv4 & DHCPv6'!$J:$J,"PASS") -> 56 | I31: =COUNTIF('DHCPv4 & DHCPv6'!$J:$J,"FAIL") -> 2 | J31: =COUNTIF('DHCPv4 & DHCPv6'!$J:$J,"NOT TESTED") -> 0 | K31: =COUNTIF('DHCPv4 & DHCPv6'!$J:$J,"NOT APPLICABLE") -> 0 | L31: =COUNTIF('DHCPv4 & DHCPv6'!$J:$J,"NOT AVAILABLE") -> 0 | N31: =IF(G31-K31=0,0,(H31+I31+L31)/(G31-K31)) -> 1
C32: User Management | G32: 50 | H32: =COUNTIF('User Management'!$J:$J,"PASS") -> 45 | I32: =COUNTIF('User Management'!$J:$J,"FAIL") -> 5 | J32: =COUNTIF('User Management'!$J:$J,"NOT TESTED") -> 0 | K32: =COUNTIF('User Management'!$J:$J,"NOT APPLICABLE") -> 0 | L32: =COUNTIF('User Management'!$J:$J,"NOT AVAILABLE") -> 0 | N32: =IF(G32-K32=0,0,(H32+I32+L32)/(G32-K32)) -> 1
C33: SECURE-DUAL-BOOT | G33: 28 | H33: =COUNTIF('SECURE-DUAL-BOOT'!$J:$J,"PASS") -> 19 | I33: =COUNTIF('SECURE-DUAL-BOOT'!$J:$J,"FAIL") -> 1 | J33: =COUNTIF('SECURE-DUAL-BOOT'!$J:$J,"NOT TESTED") -> 0 | K33: =COUNTIF('SECURE-DUAL-BOOT'!$J:$J,"NOT APPLICABLE") -> 0 | L33: =COUNTIF('SECURE-DUAL-BOOT'!$J:$J,"NOT AVAILABLE") -> 8 | N33: =IF(G33-K33=0,0,(H33+I33+L33)/(G33-K33)) -> 1
C34: Device Management | G34: 45 | H34: =COUNTIF('Device Management'!$J:$J,"PASS") -> 38 | I34: =COUNTIF('Device Management'!$J:$J,"FAIL") -> 0 | J34: =COUNTIF('Device Management'!$J:$J,"NOT TESTED") -> 0 | K34: =COUNTIF('Device Management'!$J:$J,"NOT APPLICABLE") -> 5 | L34: =COUNTIF('Device Management'!$J:$J,"NOT AVAILABLE") -> 2 | N34: =IF(G34-K34=0,0,(H34+I34+L34)/(G34-K34)) -> 1
C35: Wireless Security - WPA2-WPA3 | G35: 14 | H35: =COUNTIF('Wireless Security - WPA2-WPA3'!$J:$J,"PASS") -> 8 | I35: =COUNTIF('Wireless Security - WPA2-WPA3'!$J:$J,"FAIL") -> 0 | J35: =COUNTIF('Wireless Security - WPA2-WPA3'!$J:$J,"NOT TESTED") -> 0 | K35: =COUNTIF('Wireless Security - WPA2-WPA3'!$J:$J,"NOT APPLICABLE") -> 0 | L35: =COUNTIF('Wireless Security - WPA2-WPA3'!$J:$J,"NOT AVAILABLE") -> 6 | N35: =IF(G35-K35=0,0,(H35+I35+L35)/(G35-K35)) -> 1
C36: CPE-Power-On-PoE-Mechanism | G36: 40 | H36: =COUNTIF('CPE-Power-On-PoE-Mechanism'!$J:$J,"PASS") -> 27 | I36: =COUNTIF('CPE-Power-On-PoE-Mechanism'!$J:$J,"FAIL") -> 2 | J36: =COUNTIF('CPE-Power-On-PoE-Mechanism'!$J:$J,"NOT TESTED") -> 0 | K36: =COUNTIF('CPE-Power-On-PoE-Mechanism'!$J:$J,"NOT APPLICABLE") -> 0 | L36: =COUNTIF('CPE-Power-On-PoE-Mechanism'!$J:$J,"NOT AVAILABLE") -> 11 | N36: =IF(G36-K36=0,0,(H36+I36+L36)/(G36-K36)) -> 1
C37: 2.4 GHz Radio | G37: 40 | H37: =COUNTIF('2.4 GHz Radio'!$J:$J,"PASS") -> 37 | I37: =COUNTIF('2.4 GHz Radio'!$J:$J,"FAIL") -> 1 | J37: =COUNTIF('2.4 GHz Radio'!$J:$J,"NOT TESTED") -> 0 | K37: =COUNTIF('2.4 GHz Radio'!$J:$J,"NOT APPLICABLE") -> 0 | L37: =COUNTIF('2.4 GHz Radio'!$J:$J,"NOT AVAILABLE") -> 2 | N37: =IF(G37-K37=0,0,(H37+I37+L37)/(G37-K37)) -> 1
C38: CPE and IDU DHCP Authentication | G38: 82 | H38: =COUNTIF('CPE and IDU DHCP Authentication'!$J:$J,"PASS") -> 77 | I38: =COUNTIF('CPE and IDU DHCP Authentication'!$J:$J,"FAIL") -> 2 | J38: =COUNTIF('CPE and IDU DHCP Authentication'!$J:$J,"NOT TESTED") -> 2 | K38: =COUNTIF('CPE and IDU DHCP Authentication'!$J:$J,"NOT APPLICABLE") -> 0 | L38: =COUNTIF('CPE and IDU DHCP Authentication'!$J:$J,"NOT AVAILABLE") -> 1 | N38: =IF(G38-K38=0,0,(H38+I38+L38)/(G38-K38)) -> 0.97560976
C39: Process Monitoring | G39: 19 | H39: =COUNTIF('Process Monitoring'!$J:$J,"PASS") -> 19 | I39: =COUNTIF('Process Monitoring'!$J:$J,"FAIL") -> 0 | J39: =COUNTIF('Process Monitoring'!$J:$J,"NOT TESTED") -> 0 | K39: =COUNTIF('Process Monitoring'!$J:$J,"NOT APPLICABLE") -> 0 | L39: =COUNTIF('Process Monitoring'!$J:$J,"NOT AVAILABLE") -> 0 | N39: =IF(G39-K39=0,0,(H39+I39+L39)/(G39-K39)) -> 1
C40: PPPoE | G40: 20 | H40: =COUNTIF(PPPoE!$J:$J,"PASS") -> 18 | I40: =COUNTIF(PPPoE!$J:$J,"FAIL") -> 0 | J40: =COUNTIF(PPPoE!$J:$J,"NOT TESTED") -> 2 | K40: =COUNTIF(PPPoE!$J:$J,"NOT APPLICABLE") -> 0 | L40: =COUNTIF(PPPoE!$J:$J,"NOT AVAILABLE") -> 0 | N40: =IF(G40-K40=0,0,(H40+I40+L40)/(G40-K40)) -> 0.9
C41: Logs | G41: 97 | H41: =COUNTIF(Logs!$J:$J,"PASS") -> 95 | I41: =COUNTIF(Logs!$J:$J,"FAIL") -> 0 | J41: =COUNTIF(Logs!$J:$J,"NOT TESTED") -> 0 | K41: =COUNTIF(Logs!$J:$J,"NOT APPLICABLE") -> 0 | L41: =COUNTIF(Logs!$J:$J,"NOT AVAILABLE") -> 2 | N41: =IF(G41-K41=0,0,(H41+I41+L41)/(G41-K41)) -> 1
C42: GPS | G42: 17 | H42: =COUNTIF(GPS!$J:$J,"PASS") -> 14 | I42: =COUNTIF(GPS!$J:$J,"FAIL") -> 0 | J42: =COUNTIF(GPS!$J:$J,"NOT TESTED") -> 0 | K42: =COUNTIF(GPS!$J:$J,"NOT APPLICABLE") -> 2 | L42: =COUNTIF(GPS!$J:$J,"NOT AVAILABLE") -> 1 | N42: =IF(G42-K42=0,0,(H42+I42+L42)/(G42-K42)) -> 1
C43: NMS-Client Communication | G43: 29 | H43: =COUNTIF('NMS-Client Communication'!$J:$J,"PASS") -> 14 | I43: =COUNTIF('NMS-Client Communication'!$J:$J,"FAIL") -> 0 | J43: =COUNTIF('NMS-Client Communication'!$J:$J,"NOT TESTED") -> 0 | K43: =COUNTIF('NMS-Client Communication'!$J:$J,"NOT APPLICABLE") -> 3 | L43: =COUNTIF('NMS-Client Communication'!$J:$J,"NOT AVAILABLE") -> 12 | N43: =IF(G43-K43=0,0,(H43+I43+L43)/(G43-K43)) -> 1
C44: API | G44: 27 | H44: =COUNTIF(API!$J:$J,"PASS") -> 21 | I44: =COUNTIF(API!$J:$J,"FAIL") -> 0 | J44: =COUNTIF(API!$J:$J,"NOT TESTED") -> 0 | K44: =COUNTIF(API!$J:$J,"NOT APPLICABLE") -> 0 | L44: =COUNTIF(API!$J:$J,"NOT AVAILABLE") -> 6 | N44: =IF(G44-K44=0,0,(H44+I44+L44)/(G44-K44)) -> 1
...

Sheet Revision History
A2: Test Plan Revision | B2: Senao Comment | C2: Airtel Comment
A3: Senao UBR P2MP Test Plan_v0.1 | B3: Provided Software test plan to Airtel on 31st March 2026 | C3: 1. Map the test case id from Senao test plan wrt Airtel software acceptance criteria. 2. Add negative test cases of SW Upgrade, Dying gasp. 3. LED's test as per Airtel Requirement. 4. Add OBSS, Channel Utilization is System Summary. 5. Alarms to be reworked as per Airtel requirement. 6. Remove SNMP 7. Remove CLI 8. add test to verify NMS traffic to separate VLAN and data traffic double tagged.
A4: Senao UBR P2MP Test Plan_v0.2 | B4: 1. Mapped the test case id from Senao test plan wrt Airtel software acceptance criteria and given to Airtel seperately along with test plan. 2. Added negative test cases of SW Upgrade, Dying gasp, and multiple other features wherevr applicable. 3. Modified LED's test as per Airtel Requirement. 4. Added OBSS, Channel Utilization is System Summary under Sanity. 5. Alarms to be reworked as per Airtel requirement. (Needs to confirm with Airtel can we remove from Device, Since we are covering Alarms part in NMS) 6. Removed almost all SNMP related test cases across all sheet. 7. Removed almost all CLI related test cases across all sheet except some logs related commands. 8. Added test to verify NMS traffic to separate VLAN and data traffic double tagged in VLAN sheet. 9. Added few test sheet like API, PPPoE, NMS Client Communications, GPS, Logs, Process Monitoring, 2.4 GHz Radio, CPE IDU Authentication etc. 10. Deleted few test cases which were duplicated. | C4: 1. Please add tests for cascaded BTS deployment. 2. Inter-op between NMS and CPE/BTS, test this rigorously and over long durations - this is one I am most worried about. 3. Mark tests in the sheet that are CPE only, BTS only and both. Just add a column for applicable device. 4. Add Revision History
A5: Senao UBR P2MP Test Plan_v0.3 | B5: 1. Added cascaded BTS test cases. 2. Added Device (BTS and CPE) and NMS Interoperability test 3. Added Additional column "Test Run DUT" with BTS, CPE, Both BTS and CPE option. 4. Added Revision History Tab to track. 5 Added test type column with type negative, functional, validation, configuration etc.. 6. Deleted few test cases from GUI which were not applicable for Airtel Like TWAMP, and VLAN Modes other than Management and QinQ 7. Deleted few test cases which were duplicated. | C5: 1. stress test (100 reboots, 100 factory reset, cable plug out plugin etc etc.) 2. stability 3. firewall/attack prevention 4. port isolation/traffic isoloation 5.compass accuracy tests? 6.can you add aim of test to this sheet, something aim: to test speed and duplex negotiation 7.can you also mention here that the aim of this test is to establish that the cable length can be accurately measured from the software? 8.please also add traffic isolation tests, like, CPE management or data traffic should not leak to other CPEs connected to the BTS, management and data traffic should not leak into each other's vlans. IDUs connected behind each CPE should not be reachable to each other. should there be broadcast/multicast domain related tests as well here? 9.please add test for validating IP allocation and duplicate address allocation prevention in cascaded BTS scenario and broadcast domain segregation test. 10. Cascaded BTS2&3 IP allocation via Primary BTS DHCP Server
A6: Senao UBR P2MP Test Plan_v0.4 | B6: 1. Added in the Sanity test Plan at the bottom. 2. Stability already available: DDRS_67 3. Do you mean Port blocking mechanism ? Such cases already added on individual test sheet like Speed test, port should open upon request and should close immediately. 4. Added at bottom of IPv4_IPv6 sheet and Cascaded BTS sheet. 5. Compass Accuracy added in Field test plan since it is going to carried out at Field. 6. Added Test Aim for both BTS & CPE in First Row 7. Added test Aim in the First Row 8. Added 14 test cases from IP_37 to IP_51 9. Added 10 test cases from CASCADED_BTS_41 to CASCADED_BTS_50. 10. Also added new req cascaded BTS2&3 should get IP from Primary BTS 1 DHCP server and it should be bind with MAC so every reboot or lease expiry it should allocate same IP to BTS2 and BTS3 | C6: 1. Stability: you will need to add more pass criteria, like latency number should be within acceptable threshold, average drop should be within acceptable threshold, no effect on user experience etc. 2. Firewall: validation that all ports except https are indeed blocked, attack prevention tests pass (like openvas i think does attack testing, you should be able to use that) 3. Compass: no reason for compass accuracy to not have a functional test. I would assum 4. One clarification, IPTV in airtel is unicast, so I don't see the value in this test from IPTV perspective. You should just verify IGMP/MLD snooping from the perspective that multicast flooding does not happen. You should add a test to verify DAD works though. 5. Management IP on CPEs is proposed to be IPv6, perhaps better to test MLD and also to verify that the request is not leaking to CPE 1 or any other CPE.
A7: Senao UBR P2MP Test Plan_v0.5 | B7: 1. Stability Testcases 102 to 109 added at the end of Sanity Test Sheet. 2. Added Test cases under Firewall Module in the Last Module. 3. Compass Testcases 97 to 101 added at the end of Sanity Test Sheet. 4. Added Testcases IP_52 to IP_60 5. Added Testcases IP_52 to IP_60 6. Added New Module in the Last for Co-channel and Adjuscent Channel Testing in Lab Conducted Setup. | C7: OK

Sheet Test Setup

Sheet RFC Results
B1: 20 MHz | Ratio 80-20 | K1: 20 MHz | Ratio 75-25 | T1: 20 MHz | Ratio Auto
B2: Frame Size | C2: Channel BW | D2: Tx/Rx ratio | E2: Throughput (Mbps) | G2: Latency (ms) | H2: Jitter (ms) | K2: Frame Size | L2: Channel BW | M2: Tx/Rx ratio | N2: Throughput (Mbps) | P2: Latency (ms) | Q2: Jitter (ms) | T2: Frame Size | U2: Channel BW | V2: Tx/Rx ratio | W2: Throughput (Mbps) | Y2: Latency (ms) | Z2: Jitter (ms)
E3: UL | F3: DL | H3: UL | I3: DL | N3: UL | O3: DL | Q3: UL | R3: DL | W3: UL | X3: DL | Z3: UL | AA3: DL
B4: Imix | C4: 20 MHz | D4: 80/20 | K4: Imix | L4: 20 MHz | M4: 80/20 | T4: Imix | U4: 20 MHz | V4: 80/20
B5: 64 | C5: 20 MHz | D5: 80/20 | K5: 64 | L5: 20 MHz | M5: 80/20 | T5: 64 | U5: 20 MHz | V5: 80/20
B6: 128 | C6: 20 MHz | D6: 80/20 | K6: 128 | L6: 20 MHz | M6: 80/20 | T6: 128 | U6: 20 MHz | V6: 80/20
B7: 256 | C7: 20 MHz | D7: 80/20 | K7: 256 | L7: 20 MHz | M7: 80/20 | T7: 256 | U7: 20 MHz | V7: 80/20
B8: 512 | C8: 20 MHz | D8: 80/20 | K8: 512 | L8: 20 MHz | M8: 80/20 | T8: 512 | U8: 20 MHz | V8: 80/20
B9: 1024 | C9: 20 MHz | D9: 80/20 | K9: 1024 | L9: 20 MHz | M9: 80/20 | T9: 1024 | U9: 20 MHz | V9: 80/20
B10: 1280 | C10: 20 MHz | D10: 80/20 | K10: 1280 | L10: 20 MHz | M10: 80/20 | T10: 1280 | U10: 20 MHz | V10: 80/20
B11: 1518 | C11: 20 MHz | D11: 80/20 | K11: 1518 | L11: 20 MHz | M11: 80/20 | T11: 1518 | U11: 20 MHz | V11: 80/20
B13: 40 MHz | Ratio 80-20 | K13: 40 MHz | Ratio 75-25 | T13: 40 MHz | Ratio Auto
B14: Frame Size | C14: Channel BW | D14: Tx/Rx ratio | E14: Throughput (Mbps) | G14: Latency (ms) | H14: Jitter (ms) | K14: Frame Size | L14: Channel BW | M14: Tx/Rx ratio | N14: Throughput (Mbps) | P14: Latency (ms) | Q14: Jitter (ms) | T14: Frame Size | U14: Channel BW | V14: Tx/Rx ratio | W14: Throughput (Mbps) | Y14: Latency (ms) | Z14: Jitter (ms)
E15: UL | F15: DL | H15: UL | I15: DL | N15: UL | O15: DL | Q15: UL | R15: DL | W15: UL | X15: DL | Z15: UL | AA15: DL
B16: Imix | C16: 20 MHz | D16: 80/20 | K16: Imix | L16: 20 MHz | M16: 80/20 | T16: Imix | U16: 20 MHz | V16: 80/20
B17: 64 | C17: 20 MHz | D17: 80/20 | K17: 64 | L17: 20 MHz | M17: 80/20 | T17: 64 | U17: 20 MHz | V17: 80/20
B18: 128 | C18: 20 MHz | D18: 80/20 | K18: 128 | L18: 20 MHz | M18: 80/20 | T18: 128 | U18: 20 MHz | V18: 80/20
B19: 256 | C19: 20 MHz | D19: 80/20 | K19: 256 | L19: 20 MHz | M19: 80/20 | T19: 256 | U19: 20 MHz | V19: 80/20
B20: 512 | C20: 20 MHz | D20: 80/20 | K20: 512 | L20: 20 MHz | M20: 80/20 | T20: 512 | U20: 20 MHz | V20: 80/20
B21: 1024 | C21: 20 MHz | D21: 80/20 | K21: 1024 | L21: 20 MHz | M21: 80/20 | T21: 1024 | U21: 20 MHz | V21: 80/20
B22: 1280 | C22: 20 MHz | D22: 80/20 | K22: 1280 | L22: 20 MHz | M22: 80/20 | T22: 1280 | U22: 20 MHz | V22: 80/20
B23: 1518 | C23: 20 MHz | D23: 80/20 | K23: 1518 | L23: 20 MHz | M23: 80/20 | T23: 1518 | U23: 20 MHz | V23: 80/20
B25: 80 MHz | Ratio 80-20 | K25: 80 MHz | Ratio 75-25 | T25: 80 MHz | Ratio Auto
B26: Frame Size | C26: Channel BW | D26: Tx/Rx ratio | E26: Throughput (Mbps) | G26: Latency (ms) | H26: Jitter (ms) | K26: Frame Size | L26: Channel BW | M26: Tx/Rx ratio | N26: Throughput (Mbps) | P26: Latency (ms) | Q26: Jitter (ms) | T26: Frame Size | U26: Channel BW | V26: Tx/Rx ratio | W26: Throughput (Mbps) | Y26: Latency (ms) | Z26: Jitter (ms)
E27: UL | F27: DL | H27: UL | I27: DL | N27: UL | O27: DL | Q27: UL | R27: DL | W27: UL | X27: DL | Z27: UL | AA27: DL
B28: Imix | C28: 20 MHz | D28: 80/20 | K28: Imix | L28: 20 MHz | M28: 80/20 | T28: Imix | U28: 20 MHz | V28: 80/20
B29: 64 | C29: 20 MHz | D29: 80/20 | K29: 64 | L29: 20 MHz | M29: 80/20 | T29: 64 | U29: 20 MHz | V29: 80/20
B30: 128 | C30: 20 MHz | D30: 80/20 | K30: 128 | L30: 20 MHz | M30: 80/20 | T30: 128 | U30: 20 MHz | V30: 80/20
B31: 256 | C31: 20 MHz | D31: 80/20 | K31: 256 | L31: 20 MHz | M31: 80/20 | T31: 256 | U31: 20 MHz | V31: 80/20
B32: 512 | C32: 20 MHz | D32: 80/20 | K32: 512 | L32: 20 MHz | M32: 80/20 | T32: 512 | U32: 20 MHz | V32: 80/20
B33: 1024 | C33: 20 MHz | D33: 80/20 | K33: 1024 | L33: 20 MHz | M33: 80/20 | T33: 1024 | U33: 20 MHz | V33: 80/20
B34: 1280 | C34: 20 MHz | D34: 80/20 | K34: 1280 | L34: 20 MHz | M34: 80/20 | T34: 1280 | U34: 20 MHz | V34: 80/20
B35: 1518 | C35: 20 MHz | D35: 80/20 | K35: 1518 | L35: 20 MHz | M35: 80/20 | T35: 1518 | U35: 20 MHz | V35: 80/20
B37: 160 MHz | Ratio 80-20 | K37: 160 MHz | Ratio 75-25 | T37: 160 MHz | Ratio Auto
B38: Frame Size | C38: Channel BW | D38: Tx/Rx ratio | E38: Throughput (Mbps) | G38: Latency (ms) | H38: Jitter (ms) | K38: Frame Size | L38: Channel BW | M38: Tx/Rx ratio | N38: Throughput (Mbps) | P38: Latency (ms) | Q38: Jitter (ms) | T38: Frame Size | U38: Channel BW | V38: Tx/Rx ratio | W38: Throughput (Mbps) | Y38: Latency (ms) | Z38: Jitter (ms)
E39: UL | F39: DL | H39: UL | I39: DL | N39: UL | O39: DL | Q39: UL | R39: DL | W39: UL | X39: DL | Z39: UL | AA39: DL
B40: Imix | C40: 20 MHz | D40: 80/20 | K40: Imix | L40: 20 MHz | M40: 80/20 | T40: Imix | U40: 20 MHz | V40: 80/20
B41: 64 | C41: 20 MHz | D41: 80/20 | K41: 64 | L41: 20 MHz | M41: 80/20 | T41: 64 | U41: 20 MHz | V41: 80/20
B42: 128 | C42: 20 MHz | D42: 80/20 | K42: 128 | L42: 20 MHz | M42: 80/20 | T42: 128 | U42: 20 MHz | V42: 80/20
B43: 256 | C43: 20 MHz | D43: 80/20 | K43: 256 | L43: 20 MHz | M43: 80/20 | T43: 256 | U43: 20 MHz | V43: 80/20
...

Sheet Sanity
A1: S.No. | B1: TRACEABILITY-ID | C1: TESTCASE-ID | D1: TEST SETUP | E1: SECTION | F1: TEST DESCRIPTION | G1: TEST STEPS | H1: EXPECTED RESULT | I1: TEST RUN DUT | J1: TEST TYPE | K1: RESULT | L1: DEFECT ID | M1: COMMENTS
A2: 1 | C2: SANITY_01 | E2: PoE Verification | F2: Power the board with PoE | G2: For BTS: Connect DC terminal Block to DC socket of BTS A60 device. For CPE: Connect IDU's POE+Data cable to any port of CPE A61. CPE should get powered ON | H2: Device power ON LED indication should show Green light | I2: BTS & CPE | J2: Physical Verification | K2: Pass
A3: 2 | C3: SANITY_02 | E3: Firmware upgrade | F3: Upgrade the Image with Keep Settings | G3: 1)Login to GUI in BTS side 2)Click on Management --> Upgrade/reset --> http/https 3)In Upgrade Firmware click on choose file and select the image and then click on upgrade button 4)Click on proceed to Flash the image (Repeat the same steps for CPE side) | H3: Image will change But the settings will remain the same. | I3: BTS & CPE | J3: Functional | K3: Pass
A4: 3 | C4: SANITY_03 | E4: Firmware upgrade | F4: Flash the Image without Keep Settings | G4: 1)Login to GUI in BTS side 2)Click on Management --> Upgrade/reset --> http/https 3)Uncheck the keep settings box 4)In Upgrade Firmware click on choose file and select the image and then click on upgrade button 5)Click on proceed to Flash the image (Repeat the same steps for CPE side) | H4: Image will change and settings will be Default. | I4: BTS & CPE | J4: Functional | K4: Pass
A5: 4 | C5: SANITY_04 | E5: Firmware upgrade | F5: Corrupt Image Upgrade | G5: Attempt upgrade with corrupt image | H5: Upgrade fails; device retains current image | I5: BTS & CPE | J5: Negative | K5: Pass
A6: 5 | C6: SANITY_05 | E6: Firmware upgrade | F6: Abort upgrade handling | G6: 1. Start upgrade 2. Abort midway | H6: Partial image cleaned; system stable | I6: BTS & CPE | J6: Negative | K6: Pass
A7: 6 | C7: SANITY_06 | E7: Firmware upgrade | F7: Power loss during upgrade | G7: Interrupt power during install | H7: System should recovers; no corruption | I7: BTS & CPE | J7: Negative | K7: Pass
A8: 7 | C8: SANITY_07 | E8: Login | F8: Device GUI Login Validation | G8: For GUI login 1)Open any Browser and enter the ip address of BTS(ex- https://192.168.2.1) 2)Then Login with the id and Password (repeat the same steps for CPE ) | H8: Should be able access device GUI defualt IP, username password. | I8: BTS & CPE | J8: Functional | K8: Pass
A9: 8 | C9: SANITY_08 | E9: Login | F9: Fallback IP Working Status Validation | G9: 1. Reboot the device 2. When device power up, login the device with IP address 10.0.0.1/24 3. Ping the IP address and check whether it is pinging | H9: Device should be login with default/configured fallback IP address. | I9: BTS & CPE | J9: Functional | K9: Pass
A10: 9 | C10: SANITY_09 | E10: Dual Bank SW Partition | F10: To Check the configuration after commit firmware in backup partition | G10: 1)Click on Wireless--> Radio and enable DCS & click on save 3)Config Tx power, Manual Frequency, Channel width and save 4)Enable ATPC and save the config 3)Click on Management --> Upgrade/Reset and click on Frimware Upgrade 4)In Commit Firmware click on Perform commit 5)Go to Backhaul Radio and check the changes (The changes you have done in Active Bank will be copied in Backup Bank) | H10: Active image Should be copied in Backup image. | I10: BTS & CPE | J10: Functional | K10: Not Available
A11: 10 | C11: SANITY_10 | E11: LED Verification | F11: Verify LED during device boot | G11: Power ON the BTS from OFF state (Perform and validate at both BTS and CPE) | H11: 1.GREEN LED blinks at 0.5 ms interval 2.BLUE LED remains OFF | I11: BTS & CPE | J11: Physical Verification | K11: Pass
A12: 11 | C12: SANITY_11 | E12: LED Verification | F12: Verify GREEN LED after boot completion | G12: Allow device to complete boot sequence (Perform and validate at both BTS and CPE) | H12: 1. GREEN LED turns solid ON 2. BLUE LED remains OFF | I12: BTS & CPE | J12: Physical Verification | K12: Fail | M12: Blue LED is keep on Blinking as soon as boot sequence completed
A13: 12 | C13: SANITY_12 | E13: LED Verification | F13: Verify GREEN LED during link provisioning | G13: Initiate link provisioning process by connecting mobile application/laptop to 2.4 GHz interface (Perform and validate at both BTS and CPE) | H13: 1.GREEN LED remains solid ON 2.BLUE LED blinks at 0.5 ms interval | I13: BTS & CPE | J13: Physical Verification | K13: Not Available
A14: 13 | C14: SANITY_13 | E14: LED Verification | F14: Verify GREEN LED when link is established | G14: Complete link provisioning Successfully by adding correct SSID and password of BTS to connect to (Perform and validate at both BTS and CPE) | H14: 1.GREEN LED remains solid ON | I14: BTS & CPE | J14: Physical Verification | K14: Pass
A15: 14 | C15: SANITY_14 | E15: LED Verification | F15: Verify GREEN LED when link goes down | G15: BTS Case: Bring down established link (BTS to MUX cable) CPE Case: Bring down established RF link (Perform and validate at both BTS and CPE) | H15: 1. GREEN LED remains solid ON 2. BLUE LED turns OFF | I15: BTS & CPE | J15: Physical Verification | K15: Fail | M15: If any link goes down the blue LED is keep on blinking
A16: 15 | C16: SANITY_15 | E16: LED Verification | F16: Verify GREEN LED during firmware upgrade | G16: Trigger firmware upgrade from GUI/NMS/Application. Try all 3 firmware upgrade uption and validate the LED (Perform and validate at both BTS and CPE) | H16: 1.GREEN LED blinks continuously 2.BLUE LED blinks continuously | I16: BTS & CPE | J16: Physical Verification | K16: Pass
A17: 16 | C17: SANITY_16 | E17: LED Verification | F17: Verify GREEN LED during factory reset | G17: Trigger factory reset (HW/GUI) (Perform and validate at both BTS and CPE) | H17: 1.GREEN LED blinks at 0.25 ms interval 2.BLUE LED blinks at 0.25 ms interval | I17: BTS & CPE | J17: Physical Verification | K17: Pass
A18: 17 | C18: SANITY_17 | E18: System config | F18: BTS ID & Site ID | G18: Configure and check whether these are applying | H18: Should be configure and apply | I18: BTS & CPE | J18: Configuration | K18: Pass
A19: 18 | C19: SANITY_18 | E19: System config | F19: Time Zone | G19: Configure timezone under System--> General and check whether these are applying | H19: Time should be changed as per Timezone | I19: BTS & CPE | J19: Configuration | K19: Pass
A20: 19 | C20: SANITY_19 | E20: Network Configuration | F20: Configure Static IPv4 | G20: 1)Login with IPv4 address in Browser 2)Select Network --> IP Configuration 3)In Address type select Static and then Config IPv4 and save 4)Page will reload again with the change IP. | H20: For GUI Should be able to access device GUI with changed IPv4 | I20: BTS & CPE | J20: Functional | K20: Pass
A21: 20 | C21: SANITY_20 | E21: Network Configuration | F21: Configure Static IPv6 | G21: 1)Login with IPv6 address in Browser 2)Select Network --> IP Configuration 3)In Address type select Static and then Config IPv6 and save 4)Page will reload again with the change IP. | H21: For GUI Should be able to access device GUI with changed IPv6 | I21: BTS & CPE | J21: Functional | K21: Pass
A22: 21 | C22: SANITY_21 | E22: Network Configuration | F22: Configure DHCP IPv4 | G22: 1)Login GUI in Browser. 2)Select Network --> IP Configuration 3)In Address type select DHCPv4 and save 4)Repeat above step for CPE side also. 5)Connect Internet/DHCP network LAN cable to DATA IN socket in BTS side PoE (NOTE:-- Use Wireshark to capture Packet and check for IP assigned from DHCP server) | H22: We should be able to login GUI with the IP which will get from DHCP server. | I22: BTS & CPE | J22: Functional | K22: Pass
A23: 22 | C23: SANITY_22 | E23: Network Configuration | F23: Configure DHCP IPv6 | G23: 1)Login GUI in Browser. 2)Select Network --> IP Configuration 3)In Address type select DHCPv6 and save 4)Repeat above step for CPE side also. 5)Connect Internet/DHCP network LAN cable to DATA IN socket in BTS side PoE (NOTE:-- Use WIRE SHARK to capture Packet and check for IP assigned from DHCP server) | H23: We should be able to login GUI with the IP which we will get from DHCP server. | I23: BTS & CPE | J23: Functional | K23: Pass
A24: 23 | C24: SANITY_23 | E24: Network Configuration | F24: Configure Management VLAN | G24: 1)Login BTS/CPE with IPv4 address in Browser 2)Select Network--> VLAN and then click on Radio 3)In VLAN settings, enable the vlan. 4)Config Management VLAN ID and save. | H24: After configuring MVLAN, user should able to access device management (GUI) by tagging same VLAN on connected switch or Laptop | I24: BTS & CPE | J24: Functional | K24: Pass
A25: 24 | C25: SANITY_24 | E25: Network Configuration | F25: Configure Data VLAN | G25: 1)Login CPE with IPv4 address in Browser 2)Select Network --> VLAN and than click on Mode 3)Select from Transparent, Trunk, QinQ. 4)Config VLAN ID and save. | H25: Traffic should be run with same vlan ID. | I25: BTS | J25: Functional | K25: Pass
A26: 25 | C26: SANITY_25 | E26: Network Configuration | F26: Dual Stack | G26: 1)Login GUI in Browser. 2)Select Network --> IP Configuration. 3)Enable both IPv4 and IPv6 at same time. 4)Repeat above step for CPE side also. | H26: We should be able to access the device with both IPv4 & IPv6 | I26: BTS & CPE | J26: Functional | K26: Pass
A27: 26 | C27: SANITY_26 | E27: Jumbo Frame | F27: Jumbo Frame | G27: 1)Login GUI in Browser. 2)Select Network --> Ethernet --> LAN 3)Configure the MTU Size 9000 and save. 4)Repeat above step for CPE side also. | H27: We should be able to login GUI with the IP. And traffic with 9000 bytes should pass. | I27: BTS & CPE | J27: Functional | K27: Pass
... A46: 45 | C46: SANITY_45 | E46: Spectrum Report | F46: Spectrum Report | G46: 1. Login with GUI 2. Select Monitoring --> Tools --> Spectrum Analyser 3. Configure Start and End Freq Range and Click Start to Run Spectrum Analyser | H46: Should have display all the information of channel, noise level, Uilization, Interference etc.. | I46: BTS & CPE | J46: Functional | K46: Pass
A47: 46 | C47: SANITY_46 | E47: ATPC | F47: Configure ATPC | G47: 1. Login with CPE GUI (in P2MP ATPC works at CPE only) 2. Select Wireless --> Radio --> DDRS/ATPC 3. Enable ATPC and save and apply. | H47: Link RSSI should be retain ATPC. And Tx power set by ATPC can be viewed at Monitor --> Radio Statistics --> Link and click on that perticular CPE. Details config of specific CPE will be visible. | I47: CPE | J47: Functional | K47: Pass | M47: ATPC Configuration is Available in Both BTS & CPE
A48: 47 | C48: SANITY_47 | E48: QoS | F48: Config QoS | G48: 1. Login with GUI 2. Select Wireless --> QoS. 3. Configure PIR and SFC as per Airtel QoS Template and check | H48: Able to config policy & priorities. | I48: BTS & CPE | J48: Functional | K48: Pass | M48: Referer to QoS Report
A49: 48 | C49: SANITY_48 | E49: Wireless Link | F49: Able to Associate BTS/CPE as per configuration | G49: 1)By Default Link come up with Unique SSID and Password generated by 3 Algo. 2)Configure BTS SSID and Password into CPE using Mobile App/API. 2)Check whether Monitor --> Radio Statistics --> Link formed or not, and IP aasigned to CPE by BTS DHCP Server pool | H49: BTS and CPE should be able to Associate with each other. After association check whether Both sides showing accurate RF Link parameters | I49: BTS & CPE | J49: Validation | K49: Pass
A50: 49 | C50: SANITY_49 | E50: Wireless Link | F50: Able to Ping BTS to CPE and Vice Versa | G50: Use ping command from BTS to CPE device and from CPE to BTS device. | H50: In both case BTS and CPE should be able to ping each other. | I50: BTS & CPE | J50: Validation | K50: Pass
A51: 50 | C51: SANITY_50 | E51: RF Link Statistics | F51: System Name | G51: 1)Login to BTS GUI 2)Go to Monitor --> Radio Statistics --> Link and check all the associated CPE's System Name (Repeat above steps for CPE Device) | H51: All Connected CPEs System name should show in list. At CPE end, BTS System should show in the link list | I51: BTS & CPE | J51: Validation | K51: Pass
A52: 51 | C52: SANITY_51 | E52: RF Link Statistics | F52: IP address | G52: 1)Go to Monitor --> Radio Statistics --> Link and check all the associated CPE's IP address 2)Login any CPE with IPv4 or IPv6 address in Browser 3)Select Network --> IP address and then click on edit. 4)In General setup select Static address in Protocol and then click on Switch Protocal 5)Config IPv4 or IPv6 and save 6)Page will reload again with the change IP. (Check in Monitor --> Radio Statistics --> Link and check all the associated CPE's, perticular CPE IP should be updated) | H52: IP address should show changed IP Monitor --> Radio Statistics --> Link. | I52: BTS & CPE | J52: Validation | K52: Pass
A53: 52 | C53: SANITY_52 | E53: RF Link Statistics | F53: Uptime (Link Uptime) | G53: 1)Go to Monitor --> Radio Statistics --> Link and check all the associated CPE's uptime 2)Login any CPE and and break the link by misalign or do soft reboot 3)Once link come up after reboot 4)Check in Monitor --> Radio Statistics --> Link and check all the associated CPE's, perticular CPE Link uptime should be updated. | H53: CPE Link uptime should be updated upon due to any reason link got disconnected from it peer. Format: (dd:hh:mm:ss) | I53: BTS & CPE | J53: Validation | K53: Pass
A54: 53 | C54: SANITY_53 | E54: RF Link Statistics | F54: Combined RSSI (DL UL) | G54: 1)Login to GUI 2)Go to Monitor --> Radio Statistics and check if combined RSSI is updating properly from the backend if we align and misalign or add attenuation (if conducted setup) | H54: Upon changing the alignment or attaenuation RSSI should vary. | I54: BTS & CPE | J54: Validation | K54: Pass
A55: 54 | C55: SANITY_54 | E55: RF Link Statistics | F55: Rate MCS (DL UL) | G55: 1)Login to GUI 2)Go to Monitoring --> Radio Statistics --> Link Overview and check if the Tx rate is updating properly based on the Configured MCS and Channel width | H55: In GUI mode 160MHz - bit rate 1201 80MHz - bit rate 1201 40MHz - bit rate 573 20MHz - bit rate 286 It should show the same value in RF Link Statistics | I55: BTS & CPE | J55: Validation | K55: Pass
A56: 55 | C56: SANITY_55 | E56: RF Link Statistics | F56: MCS (DL UL) | G56: Case 1 1)Login with GUI. 2)Select Wireless --> Radio --> DDRS/ATPC 3)In Advanced setting select Max MCS 9 in MCS Auto Range and save. Check Link Table. Case 2 1)Login with GUI. 2)Select Wireless --> Radio --> DDRS/ATPC 3)In Advanced setting select Max MSC 11 in MCS Auto Range and save. Check Link Table. | H56: It should show the MSC between 0 - 7/11 in Link table | I56: BTS & CPE | J56: Validation | K56: Pass
A57: 56 | C57: SANITY_56 | E57: RF Link Statistics | F57: Throughput (OUT, IN) | G57: Case 1 1)Login with GUI. 2)Check Monitor--> Radio Statistics -->Link table when there is no Traffic on Link 3) Push traffic of 40 DL and 10 UL 4) Check traffic on Link Table 5) Push traffic of 40 DL and 10 UL on 16 CPE's 6) Check traffic on Link table | H57: Through IN and Out should increase as we start pushing traffic on Link. In ideal case it should be zero or very small (equivalent to zero) | I57: BTS & CPE | J57: Validation | K57: Pass
A58: 57 | C58: SANITY_57 | E58: RF Link Statistics | F58: Tx Power | G58: 1)Login with GUI. 2)Select Wireless --> Radio --> ATPC/DDRS 3)Select Any specific value from (3 - 30) in Tx Power and save. 4) Check Monitor--> Radio Statistics -->Link table--> Detailed Link Statistics | H58: It should show specific value in Tx power textbox and detailed statistics | I58: BTS & CPE | J58: Validation | K58: Pass
...

Sheet Tx Power Measurement
A1: S.No | B1: Freq | C1: Tx Power set in GUI | D1: Tx Power at power meter | E1: Test Run DUT
A2: 1 | B2: 5140
A3: 2 | B3: 5220
A4: 3 | B4: 5450
A5: 4 | B5: 5480
A6: 5 | B6: 5675
A7: 6 | B7: 5695
A8: 7 | B8: 5835
A9: 8 | B9: 5845
A10: 9 | B10: 5875
A11: 10 | B11: 5900
A12: 11 | B12: 5950
A13: 12 | B13: 6000
... A19: 18 | B19: 6425

Sheet GUI
A1: S.No | B1: TRACEABILITY-ID | C1: TESTCASE-ID | D1: TEST SETUP | E1: SECTION | F1: TEST DESCRIPTION | G1: TEST STEPS | H1: EXPECTED RESULT | I1: TEST RUN DUT | J1: TEST TYPE | K1: RESULT | L1: DEFECT ID | M1: COMMENTS
A2: 1 | C2: GUI_01 | E2: Summary-System | F2: Model Hardware Version Bootloader Version Local Time Temperature GPS Elevation CPU / Memory | G2: 1.Verify this parameter value in the back end using linux cmd. 2.Verify the Proper value is updated in the Summary page | H2: Value should update in Summary page as same as available in the backend. | I2: BTS & CPE | J2: Validation | K2: Pass
A3: 2 | C3: GUI_02 | E3: Summary-Network | F3: IP Address Gateway MAC Address (LAN 1, LAN 2) Speed / Duplex (LAN 1, LAN 2) Cable Length (LAN 1, LAN 2) | G3: 1.Verify this parameter value in the back end using linux cmd . 2.Verify the Proper value is updated in the Summary page | H3: Value should update in overview page as same as available in the backend. | I3: BTS & CPE | J3: Validation | K3: Pass
A4: 3 | C4: GUI_03 | E4: Summary-Performance | F4: Tx/ Rx rate for: Radio LAN 1 LAN 2 | G4: 1.Verify this parameter value in the back end using linux cmd . 2.Verify the Proper value is updated in the Summary page | H4: Value should update in overview page as same as available in the backend. | I4: BTS & CPE | J4: Validation | K4: Pass
A5: 4 | C5: GUI_04 | E5: Summary-Wireless | F5: Radio Status MAC Address Link Type Radio Mode Bandwidth SSID Configured Channel Active Channel Security RTX Percentage Remote Partners | G5: 1.Verify this parameter value in the back end using linux cmd . 2.Verify the Proper value is updated in the overview page 3.verify by increaseing/decreasing the iperf traffic on the link and check respective interface Tx/Rx rate getting updated | H5: Value should update in overview page as same as available in the backend. | I5: BTS & CPE | J5: Validation | K5: Pass
A6: 5 | C6: GUI_05 | E6: GUI Top Panel - Logo | F6: Senao Logo on top left of GUI page | G6: 1. ck on the Senao logo. 2.Verify that it is hyperlinked with device management ip and should reload the same page of device management ip | H6: It should hyperlinked to the device management ip and upon cking GUI page should getting reloaded with IP. | I6: BTS & CPE | J6: Validation | K6: Pass
A7: 6 | C7: GUI_06 | E7: GUI Top Panel | F7: Model SW Version Sr No. Uptime | G7: 1.Verify this parameter value in the back end using linux cmd . 2.Verify the Proper value is updated in the overview page. | H7: Value should update in overview page as same as available in the backend. | I7: BTS & CPE | J7: Validation | K7: Pass
A8: 7 | C8: GUI_07 | E8: GUI Top Panel | F8: Radio 2.4 GHz | G8: 1. ck on the Radio and verify it is redicting to Radio Statatics 2. ck on the 2.4 GHz and verify it is redicting to 2.4GHz Statatatics | H8: User should able to ck Radio and 2.4 GHz. And Is should redirecting to Radio and 2.4 GHz statatics respectivily. | I8: BTS & CPE | J8: Validation | K8: Pass | M8: 2.4 GHz is not supported for A60
A9: 8 | C9: GUI_08 | E9: GUI Top Panel | F9: Home Button Apply Button | G9: 1. Navigate to any module other than Home. 2. ck on the Home button, page should be redirected to Home page. 3. Change any parameters of the device and ck on the apply button 4. Once applied check whrether required changes are applied in both GUI and | H9: After cking home or applying button, It should work and canges should applied as expected. | I9: BTS & CPE | J9: Validation | K9: Pass
A10: 9 | C10: GUI_09 | E10: GUI Top Panel | F10: Reboot | G10: Check if clicking the Reboot button, device is getting rebooted. And no configuration getting erased. | H10: Upon cking reboot buttom, device should initiated soft reboot and no configuration should be erased | I10: BTS & CPE | J10: Validation | K10: Pass
A11: 10 | C11: GUI_10 | E11: GUI Top Panel | F11: Logout | G11: Check upon cking the Logout button, User is getting Logged out properly or not ? | H11: Upon cking logout button user should logged out. | I11: BTS & CPE | J11: Validation | K11: Pass
A12: 11 | C12: GUI_11 | E12: Quick Start - System | F12: IP address type IPv4/v6 address Subnet/Prefix Length Gateway | G12: 1. Navigate to Quick Start Module --> System Tab. 2. Change values of these parameters and verify this parameter value in the back end using linux cmd . 3. Verify the Proper value is updated in the System page | H12: Upon changing the values of any parameters, it should be applied in GUI. | I12: BTS & CPE | J12: Configuration | K12: Pass
A13: 12 | C13: GUI_12 | E13: Quick Start - Location | F13: BTS/CPE ID Site ID Email Address Phone Number Distance Unit | G13: 1. Navigate to Quick Start Module --> Location tab 2. Change values of these parameters and verify this parameter value in the back end using linux cmd . 3. Verify the Proper value is updated in the Location page | H13: Upon changing the values of any parameters, it should be applied in GUI. Also make sure its meeting Remarks column crieteria | I13: BTS & CPE | J13: Configuration | K13: Pass
A14: 13 | C14: GUI_13 | E14: Quick Start - Radio | F14: Radio Mode -> Fixed Cascaded-->BTS SSID Bandwidth Enable 6GHz-->BTS Configured Channel Active Channel | G14: 1. Navigate to Quick Start Module --> Radio Tab 2. Change values of these parameters and verify this parameter value in the back end using linux cmd . 3. Verify the Proper value is updated in the Radio page | H14: Upon changing the values of any parameters, it should be applied in GUI. | I14: BTS & CPE | J14: Configuration | K14: Pass
A15: 14 | C15: GUI_14 | E15: Quick Start - 2.4 GHz Radio | F15: Radio Mode -> AP (Fixed) SSID Bandwidth Active Channel | G15: 1. Navigate to Quick Start Module --> 2.4 GHz Radio Tab 2. Change values of these parameters and verify this parameter value in the back end using linux cmd . 3. Verify the Proper value is updated in the 2.4GHz Radio page | H15: Upon changing the values of any parameters, it should be applied in GUI. | I15: BTS & CPE | J15: Configuration | K15: Pass | M15: 2.4 GHz is not supported for A60
A16: 15 | C16: GUI_15 | E16: Quick Start - Link Statistics | F16: Index System Name IP Address Uptime Distance Local SNR (dB) (Chain 1, Chain 2) Remote SNR (dB) (Chain 1, Chain 2) Mbps (MCS) (Tx, Rx) Throughput (Mbps) (Out, IN) | G16: 1. Navigate to Quick Start Module -->Link Statistics Tab 2. Change values of these parameters and verify this parameter value in the back end using linux cmd . 3. Verify the Proper value is updated in the 2.4GHz Radio page. | H16: All the parameters should show correct values along with units and should varies as per interference or other conditions varies. | I16: BTS & CPE | J16: Validation | K16: Pass
A17: 16 | C17: GUI_16 | E17: Quick Start - Site Survey | F17: Index SSID MAC Address Channel Frequency (MHz) RSSI (dBm) Utility Security Bandwidth (MHz) Type Join Wifi Analyser Graph | G17: 1. Navigate to Quick Start Module --> Site Survey Tab 2. Run the site Survey and verify RESULTs in the back end using linux cmd . 3. Verify the Proper value is updated in the 2.4GHz Radio page. 4. Also verify the values and numbers are showing are correct value. | H17: Site Survey should all the mentioned parameters format and it should be as per interference condition and availlable in proximity. | I17: BTS & CPE | J17: Functional | K17: Pass
A18: 17 | C18: GUI_17 | E18: Wireless - Radio -Properties | F18: Status (enable/disable) | G18: 1. Navigate to Wireless --> Radio --> Properties 2. Change Radio Status enable to disable and vice versa and verify this parameter value in the back end using linux cmd . 3. Verify the Proper value is updated in the GUI page. | H18: When disable Radio transmission should be disabled. When enabled it should start transmit. | I18: BTS & CPE | J18: Configuration | K18: Pass
A19: 18 | C19: GUI_18 | E19: Wireless - Radio -Properties | F19: SSID | G19: 1. Navigate to Wireless --> Radio --> Properties 2. Change Radio SSID and verify this parameter value in the back end using linux cmd . 3. Verify the Proper value is updated in the GUI page. | H19: Upon changing the SSID, it should be applied in GUI. And there should be no Link, till the time same SSID should be configured at Far end. | I19: BTS & CPE | J19: Configuration | K19: Pass
A20: 19 | C20: GUI_19 | E20: Wireless - Radio -Properties | F20: Bandwidth | G20: 1. Navigate to Wireless --> Radio --> Properties 2. Change Radio Channel BW from 20 to 40, 80 and vice versa and verify this parameter value in the back end using linux cmd . 3. Verify the Proper value is updated in the GUI page and MCS and Tx/Rx value are updating accordingly. | H20: Upon changing the Link type, it should be applied in GUI. | I20: BTS | J20: Configuration | K20: Pass
A21: 20 | C21: GUI_20 | E21: Wireless - Radio -Properties | F21: Configured Channel & Active Channel | G21: 1. Navigate to Wireless --> Radio --> Properties 2. Change randomely few channels (including edge channels) and verify configured and active channel in the back end using linux cmd . 3. Verify the Proper value is updated in the configured channel and Active channel. | H21: Upon chaning the channel, Active channel should be shown to same as the configured channel. | I21: BTS | J21: Configuration | K21: Pass
A22: 21 | C22: GUI_21 | E22: Wireless - Radio -Properties | F22: Encryption | G22: 1. Navigate to Wireless --> Radio --> Properties 2. Change encryption from AES-256 to None and vice versa and verify this parameter value in the back end using linux cmd . 3. Verify the Proper value is updated in the GUI page. | H22: AES-256 to None or vice versa after apply, it should be updated in GUI and backend. | I22: BTS & CPE | J22: Configuration | K22: Pass
A23: 22 | C23: GUI_22 | E23: Wireless - Radio -Properties | F23: Maximum CPEs | G23: 1. Navigate to Wireless --> Radio --> Properties 2. Configure Max CPE's count and verify this parameter value in the back end using linux cmd . 3. Verify the Proper value is updated in the GUI page. | H23: Change in Max CPE count should immediately updated in both GUI and and CPE should not connect more than limit | I23: BTS & CPE | J23: Configuration | K23: Not Available
A24: 23 | C24: GUI_23 | E24: Wireless - Radio -Properties | F24: DL/UL Ratio | G24: 1. Navigate to Wireless --> Radio --> Properties 2. Change different combination of DL/UL ratio and verify this parameter value in the back end using linux cmd . 3. Verify the Proper value is updated in the GUI page. | H24: Configure the different DL/UL Ratio and save and apply should immediately updated in GUI. | I24: BTS | J24: Configuration | K24: Pass
A25: 24 | C25: GUI_24 | E25: Wireless - Radio -DDRS | F25: DDRS Status | G25: 1. Navigate to Wireless --> Radio --> DDRS/ATPC 2. Change DDRS Status enable to disable and vice versa and verify this parameter value in the back end using linux cmd . 3. Verify the Proper value is updated in the GUI page. | H25: Upon enable/disable the DDRS option it should apply in GUI and and Feature also should stop/start working. | I25: BTS & CPE | J25: Configuration | K25: Pass
A26: 25 | C26: GUI_25 | E26: Wireless - Radio -DDRS | F26: Spatial Stream | G26: 1. Navigate to Wireless --> Radio --> DDRS/ATPC 2. Change Spatial Streams Auto/Single/Dual and verify this parameter value in the back end using linux cmd . 3. Verify the Proper value is updated in the GUI page. | H26: Spatial stream Auto/Single/dual should update GUI & immediately upon changes. Sysem should show Thput as per configured spatial stream | I26: BTS & CPE | J26: Configuration | K26: Pass
A27: 26 | C27: GUI_26 | E27: Wireless - Radio -DDRS | F27: Modulation Index | G27: 1. Navigate to Wireless --> Radio --> DDRS/ATPC 2.Configure max. Data rate - Single Stream/Max. Data Rate - Dual stream for Single/Dual Spatial stream and verify this parametrs in GUI. 3. Verify the Proper value is updated in the GUI page. 4. Also verify MCS vs Throughput table is maintained with different Modulation Index configured | H27: Configured Modulation Index should immediately applied in GUI and . And Tx/Rx rate should be shown as per configured Modulation Index. | I27: BTS & CPE | J27: Configuration | K27: Pass
... A31: 30 | C31: GUI_30 | E31: Wireless - Radio - DCS | F31: DCS Status | G31: 1. Navigate to Wireless --> Radio --> DCS 2. Change DCS status enable/disable and verify this parameter value in the back end using linux cmd . 3. Verify the Proper value is updated in the GUI page. | H31: DCS enable/disable status should be updated in the GUI and after changes. Also DCS should select dynamically select best channel. | I31: BTS | J31: Configuration | K31: Pass
A32: 31 | C32: GUI_31 | E32: Wireless - Radio - DCS | F32: RTx Threshold | G32: 1. Navigate to Wireless --> Radio --> DCS 2. Configure RTx Threshold value and verify this parameter value in the back end using linux cmd . 3. Verify the Proper value is updated in the GUI page. | H32: Configured RTx Threshold should updated in GUI. And Channel switching taking effect based on the configured RTx Threshold. | I32: BTS | J32: Configuration | K32: Fail | M32: DCS trigger is not happening
A33: 32 | C33: GUI_32 | E33: Wireless - Radio - DCS | F33: DCS Frequency Band Selelection | G33: 1. Navigate to Wireless --> Radio --> DCS 2. Click on the add button, add start and end range of Freq for DCS and verify this parameter value in the back end using linux cmd. 3. Verify the Proper value is updated in the GUI page. | H33: DCS freq band selection should should work as per range selection (start and end freq) during scan. Corner freqs should work as expected. | I33: BTS | J33: Configuration | K33: Fail | M33: DCS trigger is not happening
A34: 33 | C34: GUI_33 | E34: Wireless - 2.4 GHz Radio | F34: 2.4 GHz Radio Status | G34: 1. Navigate to Wireless --> 2.4 GHz Radio 2. Change traffic shaping status enable/disable and verify this parameter value in the back end using linux cmd . 3. Verify the Proper value is updated in the GUI page. | H34: 2.4 GHz Radio should start/stop radiating upon enable/disable. Change in status should also be applied in GUI and . | I34: CPE | J34: Configuration | K34: Pass
A35: 34 | C35: GUI_34 | E35: Wireless - 2.4 GHz Radio | F35: SSID | G35: 1. Navigate to Wireless --> 2.4 GHz Radio 2. Change SSID and verify this parameter value in the back end using linux cmd . 3. Verify the Proper value is updated in the GUI page. | H35: 2.4 GHz Radio SSID should be applied immediately in GUI and and same should be start broadcasting once changes applied. | I35: CPE | J35: Configuration | K35: Pass
A36: 35 | C36: GUI_35 | E36: Wireless - 2.4 GHz Radio | F36: Bandwidth | G36: 1. Navigate to Wireless --> 2.4 GHz Radio 2. Change Channel BW 20/40 MHz and verify this parameter value in the back end using linux cmd . 3. Verify the Proper value is updated in the GUI page. | H36: 2.4 GHz Radio CBW should be immediately applied in GUI and upon changes. | I36: CPE | J36: Configuration | K36: Pass
A37: 36 | C37: GUI_36 | E37: Wireless - 2.4 GHz Radio | F37: Configured Channel & Active Channel | G37: 1. Navigate to Wireless --> 2.4 GHz Radio 2. It should be Auto and user should not able to configure and verify configured and active channel in the back end using linux cmd . 3. Verify the Proper value is updated in the configured channel and Active channel. | H37: 2.4 GHz Radio, Upon chaning the channel, Active channel should be shown to same as the configured channel. | I37: CPE | J37: Configuration | K37: Pass
A38: 37 | C38: GUI_37 | E38: Wireless - 2.4 GHz Radio | F38: Encryption | G38: 1. Navigate to Wireless --> 2.4 GHz Radio 2. Change encryption from WPA2-PSK to None and vice versa and verify this parameter value in the back end using linux cmd . 3. Verify the Proper value is updated in the GUI page. | H38: 2.4 GHz Radio Change in encryption type from WPA2-PSK to None or vice versa should be updated in GUI and immediately after applied. And associated ents should get disconnected. | I38: CPE | J38: Configuration | K38: Pass
A39: 38 | C39: GUI_38 | E39: Wireless - 2.4 GHz Radio | F39: Key | G39: 1. Navigate to Wireless --> 2.4 GHz Radio 2. Change encryption key and verify this parameter value in the back end using linux cmd . 3. Verify the Proper value is updated in the GUI page and link forming as expected with correct encryption key. | H39: Change of key should immediately take effect and updated in GUI and , and link should be formed once ent end key also changed to same. | I39: CPE | J39: Configuration | K39: Pass
A40: 39 | C40: GUI_39 | E40: Network - IP Configuration | F40: IP Version (IPv4/IPv6) | G40: 1. Navigate to Network --> IP Configuration 2. Configure IP version and and verify this parameter value in the back end using linux cmd . 3. Verify the Proper value is updated in the GUI page. | H40: IPv4 and IPv6 version should be updated immediately after apply. And IPv4/IPv6 respective field should be shown. | I40: BTS & CPE | J40: Configuration | K40: Pass
A41: 40 | C41: GUI_40 | E41: Network - IP Configuration | F41: IP Address | G41: 1. Navigate to Network --> IP Configuration 2. Configure IPv4/IPv6 and verify this parameter value in the back end using linux cmd . 3. Verify the Proper value is updated in the GUI page. 4. Check by opening new tab with updated ip and verify proper login is happening. | H41: IPv4/IPv6 address configuration should take effect immediately after apply. And device should login through GUI and using the updated Ip address. | I41: BTS & CPE | J41: Configuration | K41: Pass
A42: 41 | C42: GUI_41 | E42: Network - IP Configuration | F42: Subnet Mask/Prefix Length | G42: 1. Navigate to Network --> IP Configuration 2. Configure Subnet Mask (Ipv4)/prefix Length (Ipv6) and verify this parameter value in the back end using linux cmd . 3. Verify the Proper value is updated in the GUI page. 4. Check by opening new tab with updated ip and verify proper login is happening. | H42: IPv4/IPv6 Subnet Mask/Prefix Length configuration should take effect immediately after apply. And device should login through GUI and using the updated Ip address and CPEbnet/prefix. | I42: BTS & CPE | J42: Configuration | K42: Pass
A43: 42 | C43: GUI_42 | E43: Network - IP Configuration | F43: Gateway | G43: 1. Navigate to Network --> IP Configuration 2. Configure Gateway IP and verify this parameter value in the back end using linux cmd . 3. Verify the Proper value is updated in the GUI page. 4. Check by opening new tab with updated ip and verify proper login is happening. | H43: IPv4/IPv6 Gateway configuration should take effect immediately after apply. And device should login through GUI and using the updated Ip address, CPEbnet/prefix and gateway. | I43: BTS & CPE | J43: Configuration | K43: Pass
...

Sheet Throughput per MCS
A1: SUMMARY
A2: A60 BTS and A61 CPE Testing on firmware v0.x.x.x original ver. 0.x.x.x
A3: Bandwidth | B3: Channel Selection Mode | C3: Unit Name | D3: Ch. No. | E3: Freq. | F3: Tx Power (dBm) | G3: MCS | H3: RSSI (dBm) | I3: Chain 0 RSSI | J3: Chain 1 RSSI | K3: SNR (dB) | L3: CINR (dB) | M3: Noise Floor | N3: Tx Data Rate (Mb/s) | O3: Tx Traffic (Mb/s) | P3: Rx Traffic (Mb/s) | Q3: MIMO | R3: Traffic Packet Size | S3: TDMA Ratio | T3: Total Rx Throughput (Mb/s) of BTS and CPE | U3: Latency (ms) | V3: Test Duration | W3: Remarks if Any
E4: (MHz)
A5: 160 MHz | B5: Manual Best CH/Auto | C5: BTS | G5: 23 | Q5: Dual | R5: 1518 | S5: 80-20 | V5: 2 min
C6: CPE | G6: 23
A7: 160 MHz | B7: Manual Best CH/Auto | C7: BTS | G7: 22 | Q7: Dual | R7: 1518 | S7: 80-20 | V7: 2 min
C8: CPE | G8: 22
A9: 160 MHz | B9: Manual Best CH/Auto | C9: BTS | G9: 21 | Q9: Dual | R9: 1518 | S9: 80-20 | V9: 2 min
C10: CPE | G10: 21
A11: 160 MHz | B11: Manual Best CH/Auto | C11: BTS | G11: 20 | Q11: Dual | R11: 1518 | S11: 80-20 | V11: 2 min
C12: CPE | G12: 20
A13: 160 MHz | B13: Manual Best CH/Auto | C13: BTS | G13: 19 | Q13: Dual | R13: 1518 | S13: 80-20 | V13: 2 min
C14: CPE | G14: 19
A15: 160 MHz | B15: Manual Best CH/Auto | C15: BTS | G15: 18 | Q15: Dual | R15: 1518 | S15: 80-20 | V15: 2 min
C16: CPE | G16: 18
A17: 160 MHz | B17: Manual Best CH/Auto | C17: BTS | G17: 17 | Q17: Dual | R17: 1518 | S17: 80-20 | V17: 2 min
C18: CPE | G18: 17
A19: 160 MHz | B19: Manual Best CH/Auto | C19: BTS | G19: 16 | Q19: Dual | R19: 1518 | S19: 80-20 | V19: 2 min
C20: CPE | G20: 16
A21: 160 MHz | B21: Manual Best CH/Auto | C21: BTS | G21: 15 | Q21: Dual | R21: 1518 | S21: 80-20 | V21: 2 min
C22: CPE | G22: 15
A23: 160 MHz | B23: Manual Best CH/Auto | C23: BTS | G23: 14 | Q23: Dual | R23: 1518 | S23: 80-20 | V23: 2 min
C24: CPE | G24: 14
A25: 160 MHz | B25: Manual Best CH/Auto | C25: BTS | G25: 13 | Q25: Dual | R25: 1518 | S25: 80-20 | V25: 2 min
C26: CPE | G26: 13
A27: 160 MHz | B27: Manual Best CH/Auto | C27: BTS | G27: 12 | Q27: Dual | R27: 1518 | S27: 80-20 | V27: 2 min
C28: CPE | G28: 12
A31: A60 BTS and A61 CPE Testing on firmware v0.x.x.x original ver. 0.x.x.x
A32: Bandwidth | B32: Channel Selection Mode | C32: Unit Name | D32: Ch. No. | E32: Freq. | F32: Tx Power (dBm) | G32: MCS | H32: RSSI (dBm) | I32: Chain 0 RSSI | J32: Chain 1 RSSI | K32: SNR (dB) | L32: CINR (dB) | M32: Noise Floor | N32: Tx Data Rate (Mb/s) | O32: Tx Traffic (Mb/s) | P32: Rx Traffic (Mb/s) | Q32: MIMO | R32: Traffic Packet Size | S32: TDMA Ratio | T32: Total Rx Throughput (Mb/s) of BTS and CPE | U32: Latency (ms) | V32: Test Duration | W32: Remarks if Any
E33: (MHz)
